Workbook

Sheet India
A1: Year | B1: headline_cpi_quarterly | C1: headline_cpi_yy | D1: Year | E1: core_cpi_quarterly | F1: cpi_yy | G1: observation_date | H1: ex_rate_quarterly_avg | I1: Year | J1: cons_quarterly (constant prices) | K1: cons_quarterly ($) | L1: cons_yy | O1: Year | P1: GFCF_quarterly (constant prices) | Q1: GFCF_quarterly ($) | R1: gfcf_yy | S1: Year | T1: g_quarterly(constant prices) | U1: g_quarterly($) | V1: g_yy | X1: Year | Y1: Imports_quarterly | Z1: exports_quarterly | AA1: netx_quarterly | AB1: netx_q ($) | AC1: netx_yy | DW1: Year | DX1: cons_quarterly (constant prices) | DY1: cons_yy | DZ1: 1USD= 86.95INR | EA1: cons_yy ($) | EB1: Year | EC1: GFCF_quarterly (constant prices) | ED1: gfcf_yy | EE1: gfcf_yy ($) | EF1: Year | EG1: g_quarterly(constant prices) | EH1: g_yy | EI1: g_yy ($) | EJ1: Year | EK1: NetX_quarterly ($) | EL1: NetX_yy
A2: 25569 | B2: 2.990122 | C2: N/A | D2: 40544 | E2: 87.9 | F2: N/A | G2: 35156 | H2: 34.814682 | I2: 35156 | J2: 4.806275e+12 | K2: =J2/H2 -> 1.3805311e+11 | L2: N/A | O2: 35156 | P2: 1.7812392e+12 | Q2: =P2/H2 -> 5.116345e+10 | R2: N/A | S2: 35156 | T2: 8.7499718e+11 | U2: =T2/H2 -> 2.5132994e+10 | V2: N/A | X2: 17168 | DW2: 35156 | DX2: 4.806275e+12 | DY2: N/A | DZ2: N/A | EA2: N/A | EB2: 35156 | EC2: 1.7812392e+12 | ED2: N/A | EE2: N/A | EF2: 35156 | EG2: 8.7499718e+11 | EH2: N/A | EI2: N/A | EJ2: 17168 | EK2: 10.875 | EL2: N/A
A3: 25659 | B3: 3.078745 | C3: N/A | D3: 40634 | E3: 90.466667 | F3: N/A | G3: 35247 | H3: 35.763939 | I3: 35247 | J3: 4.8165102e+12 | K3: =J3/H3 -> 1.3467505e+11 | L3: N/A | O3: 35247 | P3: 1.8316702e+12 | Q3: =P3/H3 -> 5.1215562e+10 | R3: N/A | S3: 35247 | T3: 8.3731309e+11 | U3: =T3/H3 -> 2.3412217e+10 | V3: N/A | X3: 17258 | DW3: 35247 | DX3: 4.8165102e+12 | DY3: N/A | DZ3: N/A | EA3: N/A | EB3: 35247 | EC3: 1.8316702e+12 | ED3: N/A | EE3: N/A | EF3: 35247 | EG3: 8.3731309e+11 | EH3: N/A | EI3: N/A | EJ3: 17258 | EK3: 11.294 | EL3: N/A
A4: 25750 | B4: 3.145516 | C4: N/A | D4: 40725 | E4: 92.5 | F4: N/A | G4: 35339 | H4: 35.841439 | I4: 35339 | J4: 4.8455616e+12 | K4: =J4/H4 -> 1.3519439e+11 | L4: N/A | O4: 35339 | P4: 1.8656317e+12 | Q4: =P4/H4 -> 5.2052367e+10 | R4: N/A | S4: 35339 | T4: 8.6827503e+11 | U4: =T4/H4 -> 2.4225451e+10 | V4: N/A | X4: 17349 | DW4: 35339 | DX4: 4.8455616e+12 | DY4: N/A | DZ4: N/A | EA4: N/A | EB4: 35339 | EC4: 1.8656317e+12 | ED4: N/A | EE4: N/A | EF4: 35339 | EG4: 8.6827503e+11 | EH4: N/A | EI4: N/A | EJ4: 17349 | EK4: 11.77 | EL4: N/A
A5: 25842 | B5: 3.162512 | C5: N/A | D5: 40817 | E5: 94.833333 | F5: N/A | G5: 35431 | H5: 35.892986 | I5: 35431 | J5: 4.8915914e+12 | K5: =J5/H5 -> 1.3628266e+11 | L5: N/A | O5: 35431 | P5: 1.9236267e+12 | Q5: =P5/H5 -> 5.3593389e+10 | R5: N/A | S5: 35431 | T5: 9.5762862e+11 | U5: =T5/H5 -> 2.6680105e+10 | V5: N/A | X5: 17441 | DW5: 35431 | DX5: 4.8915914e+12 | DY5: N/A | DZ5: N/A | EA5: N/A | EB5: 35431 | EC5: 1.9236267e+12 | ED5: N/A | EE5: N/A | EF5: 35431 | EG5: 9.5762862e+11 | EH5: N/A | EI5: N/A | EJ5: 17441 | EK5: 9.289 | EL5: N/A
A6: 25934 | B6: 3.095741 | C6: =(B6/B2-1)*100 -> 3.5322639 | D6: 40909 | E6: 96.833333 | F6: =(E6/E2-1)*100 -> 10.163064 | G6: 35521 | H6: 35.824379 | I6: 35521 | J6: 4.9222525e+12 | K6: =J6/H6 -> 1.3739952e+11 | L6: =(K6/K2-1)*100 -> -0.4734313 | O6: 35521 | P6: 1.9153111e+12 | Q6: =P6/H6 -> 5.3463902e+10 | R6: =(Q6/Q2-1)*100 -> 4.496281 | S6: 35521 | T6: 8.7576638e+11 | U6: =T6/H6 -> 2.4446101e+10 | V6: =(U6/U2-1)*100 -> -2.733033 | X6: 17533 | DW6: 35521 | DX6: 4.9222525e+12 | DY6: =(DX6/DX2-1)*100 -> 2.4130438 | DZ6: 86.95 | EA6: =DY6/DZ6 -> 0.027752085 | EB6: 35521 | EC6: 1.9153111e+12 | ED6: =(EC6/EC2-1)*100 -> 7.526888 | EE6: =ED6/DZ6 -> 0.086565704 | EF6: 35521 | EG6: 8.7576638e+11 | EH6: =(EG6/EG2-1)*100 -> 0.087909063 | EI6: =EH6/DZ6 -> 0.00101103 | EJ6: 17533 | EK6: 7.293 | EL6: =(EK6/EK2-1)*100 -> -32.937931
A7: 26024 | B7: 3.112737 | C7: =(B7/B3-1)*100 -> 1.1040862 | D7: 41000 | E7: 99.1 | F7: =(E7/E3-1)*100 -> 9.5431098 | G7: 35612 | H7: 36.077137 | I7: 35612 | J7: 4.9946703e+12 | K7: =J7/H7 -> 1.384442e+11 | L7: =(K7/K3-1)*100 -> 2.7986978 | O7: 35612 | P7: 1.9358378e+12 | Q7: =P7/H7 -> 5.3658299e+10 | R7: =(Q7/Q3-1)*100 -> 4.7695214 | S7: 35612 | T7: 9.2402672e+11 | U7: =T7/H7 -> 2.5612529e+10 | V7: =(U7/U3-1)*100 -> 9.3981372 | X7: 17624 | DW7: 35612 | DX7: 4.9946703e+12 | DY7: =(DX7/DX3-1)*100 -> 3.6989444 | DZ7: 86.95 | EA7: =DY7/DZ7 -> 0.042541052 | EB7: 35612 | EC7: 1.9358378e+12 | ED7: =(EC7/EC3-1)*100 -> 5.6870274 | EE7: =ED7/DZ7 -> 0.06540572 | EF7: 35612 | EG7: 9.2402672e+11 | EH7: =(EG7/EG3-1)*100 -> 10.356178 | EI7: =EH7/DZ7 -> 0.11910498 | EJ7: 17624 | EK7: 5.205 | EL7: =(EK7/EK3-1)*100 -> -53.913582
A8: 26115 | B8: 3.252349 | C8: =(B8/B4-1)*100 -> 3.3963585 | D8: 41091 | E8: 100.83333 | F8: =(E8/E4-1)*100 -> 9.009009 | G8: 35704 | H8: 37.650675 | I8: 35704 | J8: 4.9848081e+12 | K8: =J8/H8 -> 1.3239625e+11 | L8: =(K8/K4-1)*100 -> -2.0697181 | O8: 35704 | P8: 1.9917458e+12 | Q8: =P8/H8 -> 5.2900666e+10 | R8: =(Q8/Q4-1)*100 -> 1.6297029 | S8: 35704 | T8: 9.8093732e+11 | U8: =T8/H8 -> 2.6053645e+10 | V8: =(U8/U4-1)*100 -> 7.5465838 | X8: 17715 | DW8: 35704 | DX8: 4.9848081e+12 | DY8: =(DX8/DX4-1)*100 -> 2.8736929 | DZ8: 86.95 | EA8: =DY8/DZ8 -> 0.033049948 | EB8: 35704 | EC8: 1.9917458e+12 | ED8: =(EC8/EC4-1)*100 -> 6.7598566 | EE8: =ED8/DZ8 -> 0.077744182 | EF8: 35704 | EG8: 9.8093732e+11 | EH8: =(EG8/EG4-1)*100 -> 12.975415 | EI8: =EH8/DZ8 -> 0.14922846 | EJ8: 17715 | EK8: 4.949 | EL8: =(EK8/EK4-1)*100 -> -57.952421
A9: 26207 | B9: 3.297268 | C9: =(B9/B5-1)*100 -> 4.2610431 | D9: 41183 | E9: 103.26667 | F9: =(E9/E5-1)*100 -> 8.8927944 | G9: 35796 | H9: 39.211335 | I9: 35796 | J9: 5.0369861e+12 | K9: =J9/H9 -> 1.284574e+11 | L9: =(K9/K5-1)*100 -> -5.7419306 | O9: 35796 | P9: 2.0040111e+12 | Q9: =P9/H9 -> 5.1107954e+10 | R9: =(Q9/Q5-1)*100 -> -4.637577 | S9: 35796 | T9: 1.1556374e+12 | U9: =T9/H9 -> 2.9472025e+10 | V9: =(U9/U5-1)*100 -> 10.464426 | X9: 17807 | DW9: 35796 | DX9: 5.0369861e+12 | DY9: =(DX9/DX5-1)*100 -> 2.9723403 | DZ9: 86.95 | EA9: =DY9/DZ9 -> 0.034184477 | EB9: 35796 | EC9: 2.0040111e+12 | ED9: =(EC9/EC5-1)*100 -> 4.1787927 | EE9: =ED9/DZ9 -> 0.04805972 | EF9: 35796 | EG9: 1.1556374e+12 | EH9: =(EG9/EG5-1)*100 -> 20.676994 | EI9: =EH9/DZ9 -> 0.23780326 | EJ9: 17807 | EK9: 4.501 | EL9: =(EK9/EK5-1)*100 -> -51.544838
A10: 26299 | B10: 3.257205 | C10: =(B10/B6-1)*100 -> 5.2156818 | D10: 41275 | E10: 105.13333 | F10: =(E10/E6-1)*100 -> 8.5714286 | G10: 35886 | H10: 40.734566 | I10: 35886 | J10: 5.4218562e+12 | K10: =J10/H10 -> 1.331021e+11 | L10: =(K10/K6-1)*100 -> -3.127683 | O10: 35886 | P10: 2.0426701e+12 | Q10: =P10/H10 -> 5.0145866e+10 | R10: =(Q10/Q6-1)*100 -> -6.2061236 | S10: 35886 | T10: 1.1974571e+12 | U10: =T10/H10 -> 2.9396584e+10 | V10: =(U10/U6-1)*100 -> 20.250606 | X10: 17899 | DW10: 35886 | DX10: 5.4218562e+12 | DY10: =(DX10/DX6-1)*100 -> 10.1499 | DZ10: 86.95 | EA10: =DY10/DZ10 -> 0.11673261 | EB10: 35886 | EC10: 2.0426701e+12 | ED10: =(EC10/EC6-1)*100 -> 6.6495204 | EE10: =ED10/DZ10 -> 0.07647522 | EF10: 35886 | EG10: 1.1974571e+12 | EH10: =(EG10/EG6-1)*100 -> 36.732481 | EI10: =EH10/DZ10 -> 0.42245522 | EJ10: 17899 | EK10: 6.478 | EL10: =(EK10/EK6-1)*100 -> -11.175099
A11: 26390 | B11: 3.31912 | C11: =(B11/B7-1)*100 -> 6.6302743 | D11: 41365 | E11: 106.33333 | F11: =(E11/E7-1)*100 -> 7.2990246 | G11: 35977 | H11: 42.560388 | I11: 35977 | J11: 5.461006e+12 | K11: =J11/H11 -> 1.2831194e+11 | L11: =(K11/K7-1)*100 -> -7.3186563 | O11: 35977 | P11: 2.0816242e+12 | Q11: =P11/H11 -> 4.8909896e+10 | R11: =(Q11/Q7-1)*100 -> -8.8493356 | S11: 35977 | T11: 1.1139696e+12 | U11: =T11/H11 -> 2.6173859e+10 | V11: =(U11/U7-1)*100 -> 2.1916218 | X11: 17989 | DW11: 35977 | DX11: 5.461006e+12 | DY11: =(DX11/DX7-1)*100 -> 9.3366673 | DZ11: 86.95 | EA11: =DY11/DZ11 -> 0.10737973 | EB11: 35977 | EC11: 2.0816242e+12 | ED11: =(EC11/EC7-1)*100 -> 7.5309169 | EE11: =ED11/DZ11 -> 0.086612041 | EF11: 35977 | EG11: 1.1139696e+12 | EH11: =(EG11/EG7-1)*100 -> 20.555992 | EI11: =EH11/DZ11 -> 0.23641164 | EJ11: 17989 | EK11: 6.283 | EL11: =(EK11/EK7-1)*100 -> 20.710855
A12: 26481 | B12: 3.476942 | C12: =(B12/B8-1)*100 -> 6.9055627 | D12: 41456 | E12: 108.6 | F12: =(E12/E8-1)*100 -> 7.7024793 | G12: 36069 | H12: 42.408748 | I12: 36069 | J12: 4.8361538e+12 | K12: =J12/H12 -> 1.140367e+11 | L12: =(K12/K8-1)*100 -> -13.867119 | O12: 36069 | P12: 2.1309567e+12 | Q12: =P12/H12 -> 5.0248045e+10 | R12: =(Q12/Q8-1)*100 -> -5.0143417 | S12: 36069 | T12: 1.0178617e+12 | U12: =T12/H12 -> 2.4001221e+10 | V12: =(U12/U8-1)*100 -> -7.8776837 | X12: 18080 | DW12: 36069 | DX12: 4.8361538e+12 | DY12: =(DX12/DX8-1)*100 -> -2.9821471 | DZ12: 86.95 | EA12: =DY12/DZ12 -> -0.034297264 | EB12: 36069 | EC12: 2.1309567e+12 | ED12: =(EC12/EC8-1)*100 -> 6.9893923 | EE12: =ED12/DZ12 -> 0.080384041 | EF12: 36069 | EG12: 1.0178617e+12 | EH12: =(EG12/EG8-1)*100 -> 3.7641978 | EI12: =EH12/DZ12 -> 0.043291521 | EJ12: 18080 | EK12: 5.179 | EL12: =(EK12/EK8-1)*100 -> 4.6474035
A13: 26573 | B13: 3.526717 | C13: =(B13/B9-1)*100 -> 6.958761 | D13: 41548 | E13: 110.46667 | F13: =(E13/E9-1)*100 -> 6.9722402 | G13: 36161 | H13: 42.460407 | I13: 36161 | J13: 5.5159565e+12 | K13: =J13/H13 -> 1.2990823e+11 | L13: =(K13/K9-1)*100 -> 1.1294285 | O13: 36161 | P13: 2.1718941e+12 | Q13: =P13/H13 -> 5.1151044e+10 | R13: =(Q13/Q9-1)*100 -> 0.084311647 | S13: 36161 | T13: 1.0870287e+12 | U13: =T13/H13 -> 2.5600997e+10 | V13: =(U13/U9-1)*100 -> -13.134584 | X13: 18172 | DW13: 36161 | DX13: 5.5159565e+12 | DY13: =(DX13/DX9-1)*100 -> 9.5090658 | DZ13: 86.95 | EA13: =DY13/DZ13 -> 0.10936246 | EB13: 36161 | EC13: 2.1718941e+12 | ED13: =(EC13/EC9-1)*100 -> 8.37735 | EE13: =ED13/DZ13 -> 0.096346751 | EF13: 36161 | EG13: 1.0870287e+12 | EH13: =(EG13/EG9-1)*100 -> -5.9368703 | EI13: =EH13/DZ13 -> -0.068279129 | EJ13: 18172 | EK13: 2.999 | EL13: =(EK13/EK9-1)*100 -> -33.370362
A14: 26665 | B14: 3.583776 | C14: =(B14/B10-1)*100 -> 10.026111 | D14: 41640 | E14: 112.26667 | F14: =(E14/E10-1)*100 -> 6.7850349 | G14: 36251 | H14: 42.877362 | I14: 36251 | J14: 5.5650859e+12 | K14: =J14/H14 -> 1.2979077e+11 | L14: =(K14/K10-1)*100 -> -2.4878099 | O14: 36251 | P14: 2284961162015 | Q14: =P14/H14 -> 5.3290619e+10 | R14: =(Q14/Q10-1)*100 -> 6.2712103 | S14: 36251 | T14: 1.2267501e+12 | U14: =T14/H14 -> 2.8610672e+10 | V14: =(U14/U10-1)*100 -> -2.6734824 | X14: 18264 | DW14: 36251 | DX14: 5.5650859e+12 | DY14: =(DX14/DX10-1)*100 -> 2.6417091 | DZ14: 86.95 | EA14: =DY14/DZ14 -> 0.030381934 | EB14: 36251 | EC14: 2284961162015 | ED14: =(EC14/EC10-1)*100 -> 11.861488 | EE14: =ED14/DZ14 -> 0.13641734 | EF14: 36251 | EG14: 1.2267501e+12 | EH14: =(EG14/EG10-1)*100 -> 2.4462695 | EI14: =EH14/DZ14 -> 0.028134209 | EJ14: 18264 | EK14: 2.203 | EL14: =(EK14/EK10-1)*100 -> -65.99259
A15: 26755 | B15: 3.824151 | C15: =(B15/B11-1)*100 -> 15.21581 | D15: 41730 | E15: 113.56667 | F15: =(E15/E11-1)*100 -> 6.8025078 | G15: 36342 | H15: 43.425591 | I15: 36342 | J15: 5.5805697e+12 | K15: =J15/H15 -> 1.2850878e+11 | L15: =(K15/K11-1)*100 -> 0.15340732 | O15: 36342 | P15: 2.3311708e+12 | Q15: =P15/H15 -> 5.368196e+10 | R15: =(Q15/Q11-1)*100 -> 9.7568473 | S15: 36342 | T15: 1.271234e+12 | U15: =T15/H15 -> 2.9273844e+10 | V15: =(U15/U11-1)*100 -> 11.843824 | X15: 18354 | DW15: 36342 | DX15: 5.5805697e+12 | DY15: =(DX15/DX11-1)*100 -> 2.1894086 | DZ15: 86.95 | EA15: =DY15/DZ15 -> 0.025180087 | EB15: 36342 | EC15: 2.3311708e+12 | ED15: =(EC15/EC11-1)*100 -> 11.988075 | EE15: =ED15/DZ15 -> 0.13787321 | EF15: 36342 | EG15: 1.271234e+12 | EH15: =(EG15/EG11-1)*100 -> 14.117477 | EI15: =EH15/DZ15 -> 0.16236317 | EJ15: 18354 | EK15: 1.643 | EL15: =(EK15/EK11-1)*100 -> -73.850072
A16: 26846 | B16: 4.138581 | C16: =(B16/B12-1)*100 -> 19.029337 | D16: 41821 | E16: 114.9 | F16: =(E16/E12-1)*100 -> 5.801105 | G16: 36434 | H16: 43.433381 | I16: 36434 | J16: 5.6796474e+12 | K16: =J16/H16 -> 1.3076687e+11 | L16: =(K16/K12-1)*100 -> 14.670864 | O16: 36434 | P16: 2.3378018e+12 | Q16: =P16/H16 -> 5.3825002e+10 | R16: =(Q16/Q12-1)*100 -> 7.1185991 | S16: 36434 | T16: 1.2839776e+12 | U16: =T16/H16 -> 2.9561999e+10 | V16: =(U16/U12-1)*100 -> 23.16873 | X16: 18445 | DW16: 36434 | DX16: 5.6796474e+12 | DY16: =(DX16/DX12-1)*100 -> 17.441414 | DZ16: 86.95 | EA16: =DY16/DZ16 -> 0.20059131 | EB16: 36434 | EC16: 2.3378018e+12 | ED16: =(EC16/EC12-1)*100 -> 9.7066794 | EE16: =ED16/DZ16 -> 0.11163519 | EF16: 36434 | EG16: 1.2839776e+12 | EH16: =(EG16/EG12-1)*100 -> 26.144596 | EI16: =EH16/DZ16 -> 0.3006854 | EJ16: 18445 | EK16: -0.74 | EL16: =(EK16/EK12-1)*100 -> -114.28847
A17: 26938 | B17: 4.334037 | C17: =(B17/B13-1)*100 -> 22.891545 | D17: 41913 | E17: 115.63333 | F17: =(E17/E13-1)*100 -> 4.6771273 | G17: 36526 | H17: 43.575475 | I17: 36526 | J17: 5.7006063e+12 | K17: =J17/H17 -> 1.3082144e+11 | L17: =(K17/K13-1)*100 -> 0.70296101 | O17: 36526 | P17: 2.417943e+12 | Q17: =P17/H17 -> 5.5488621e+10 | R17: =(Q17/Q13-1)*100 -> 8.479938 | S17: 36526 | T17: 1.2188541e+12 | U17: =T17/H17 -> 2.7971102e+10 | V17: =(U17/U13-1)*100 -> 9.2578645 | X17: 18537 | DW17: 36526 | DX17: 5.7006063e+12 | DY17: =(DX17/DX13-1)*100 -> 3.3475579 | DZ17: 86.95 | EA17: =DY17/DZ17 -> 0.038499804 | EB17: 36526 | EC17: 2.417943e+12 | ED17: =(EC17/EC13-1)*100 -> 11.328769 | EE17: =ED17/DZ17 -> 0.13029061 | EF17: 36526 | EG17: 1.2188541e+12 | EH17: =(EG17/EG13-1)*100 -> 12.127125 | EI17: =EH17/DZ17 -> 0.1394724 | EJ17: 18537 | EK17: -0.154 | EL17: =(EK17/EK13-1)*100 -> -105.13505
... A53: 30225 | B53: 8.322081 | C53: =(B53/B49-1)*100 -> 7.3778247 | D53: 45200 | E53: 181.1 | F53: =(E53/E49-1)*100 -> 4.0405975 | G53: 39814 | H53: 49.741947 | I53: 39814 | J53: 9.8397274e+12 | K53: =J53/H53 -> 1.9781549e+11 | L53: =(K53/K49-1)*100 -> -15.655729 | O53: 39814 | P53: 5.3122549e+12 | Q53: =P53/H53 -> 1.0679628e+11 | R53: =(Q53/Q49-1)*100 -> -27.18737 | S53: 39814 | T53: 2.0852753e+12 | U53: =T53/H53 -> 4.1921868e+10 | V53: =(U53/U49-1)*100 -> -22.382182 | X53: 21824 | DW53: 39814 | DX53: 9.8397274e+12 | DY53: =(DX53/DX49-1)*100 -> 5.3506571 | DZ53: 86.95 | EA53: =DY53/DZ53 -> 0.061537172 | EB53: 39814 | EC53: 5.3122549e+12 | ED53: =(EC53/EC49-1)*100 -> -9.0530005 | EE53: =ED53/DZ53 -> -0.10411731 | EF53: 39814 | EG53: 2.0852753e+12 | EH53: =(EG53/EG49-1)*100 -> -3.0510553 | EI53: =EH53/DZ53 -> -0.035089768 | EJ53: 21824 | EK53: 0.627 | EL53: =(EK53/EK49-1)*100 -> -341.15385
A54: 30317 | B54: 8.394921 | C54: =(B54/B50-1)*100 -> 8.9491082 | G54: 39904 | H54: 48.686616 | I54: 39904 | J54: 1.0101631e+13 | K54: =J54/H54 -> 2.0748271e+11 | L54: =(K54/K50-1)*100 -> -8.9355743 | O54: 39904 | P54: 5.9567502e+12 | Q54: =P54/H54 -> 1.2234882e+11 | R54: =(Q54/Q50-1)*100 -> -15.906762 | S54: 39904 | T54: 1.7906593e+12 | U54: =T54/H54 -> 3.6779293e+10 | V54: =(U54/U50-1)*100 -> -1.6035004 | X54: 21916 | DW54: 39904 | DX54: 1.0101631e+13 | DY54: =(DX54/DX50-1)*100 -> 6.4282696 | DZ54: 86.95 | EA54: =DY54/DZ54 -> 0.073930645 | EB54: 39904 | EC54: 5.9567502e+12 | ED54: =(EC54/EC50-1)*100 -> -1.7190552 | EE54: =ED54/DZ54 -> -0.019770617 | EF54: 39904 | EG54: 1.7906593e+12 | EH54: =(EG54/EG50-1)*100 -> 14.997367 | EI54: =EH54/DZ54 -> 0.17248266 | EJ54: 21916 | EK54: 2.858 | EL54: =(EK54/EK50-1)*100 -> 450.67437
A55: 30407 | B55: 8.760341 | C55: =(B55/B51-1)*100 -> 12.311287 | G55: 39995 | H55: 48.302637 | I55: 39995 | J55: 1.0373051e+13 | K55: =J55/H55 -> 2.1475124e+11 | L55: =(K55/K51-1)*100 -> -1.5095991 | O55: 39995 | P55: 6.2219327e+12 | Q55: =P55/H55 -> 1.2881145e+11 | R55: =(Q55/Q51-1)*100 -> -6.2597646 | S55: 39995 | T55: 1.7434464e+12 | U55: =T55/H55 -> 3.6094228e+10 | V55: =(U55/U51-1)*100 -> 13.713524 | X55: 22007 | DW55: 39995 | DX55: 1.0373051e+13 | DY55: =(DX55/DX51-1)*100 -> 8.5508769 | DZ55: 86.95 | EA55: =DY55/DZ55 -> 0.098342461 | EB55: 39995 | EC55: 6.2219327e+12 | ED55: =(EC55/EC51-1)*100 -> 3.3154974 | EE55: =ED55/DZ55 -> 0.03813108 | EF55: 39995 | EG55: 1.7434464e+12 | EH55: =(EG55/EG51-1)*100 -> 25.328993 | EI55: =EH55/DZ55 -> 0.29130527 | EJ55: 22007 | EK55: 3.395 | EL55: =(EK55/EK51-1)*100 -> -542.05729
A56: 30498 | B56: 9.219238 | C56: =(B56/B52-1)*100 -> 12.989138 | G56: 40087 | H56: 46.561111 | I56: 40087 | J56: 1.0510507e+13 | K56: =J56/H56 -> 2.2573573e+11 | L56: =(K56/K52-1)*100 -> 12.964736 | O56: 40087 | P56: 6.2941278e+12 | Q56: =P56/H56 -> 1.3517993e+11 | R56: =(Q56/Q52-1)*100 -> 11.952009 | S56: 40087 | T56: 2.413328e+12 | U56: =T56/H56 -> 5.1831409e+10 | V56: =(U56/U52-1)*100 -> 12.192351 | X56: 22098 | DW56: 40087 | DX56: 1.0510507e+13 | DY56: =(DX56/DX52-1)*100 -> 7.7595058 | DZ56: 86.95 | EA56: =DY56/DZ56 -> 0.08924101 | EB56: 40087 | EC56: 6.2941278e+12 | ED56: =(EC56/EC52-1)*100 -> 6.7934441 | EE56: =ED56/DZ56 -> 0.078130467 | EF56: 40087 | EG56: 2.413328e+12 | EH56: =(EG56/EG52-1)*100 -> 7.0227112 | EI56: =EH56/DZ56 -> 0.080767237 | EJ56: 22098 | EK56: 4.682 | EL56: =(EK56/EK52-1)*100 -> 286.62263
A57: 30590 | B57: 9.408625 | C57: =(B57/B53-1)*100 -> 13.056157 | G57: 40179 | H57: 45.880349 | I57: 40179 | J57: 1.0509539e+13 | K57: =J57/H57 -> 2.2906406e+11 | L57: =(K57/K53-1)*100 -> 15.796829 | O57: 40179 | P57: 6.6017709e+12 | Q57: =P57/H57 -> 1.4389104e+11 | R57: =(Q57/Q53-1)*100 -> 34.734127 | S57: 40179 | T57: 2.3526773e+12 | U57: =T57/H57 -> 5.127854e+10 | V57: =(U57/U53-1)*100 -> 22.319309 | X57: 22190 | DW57: 40179 | DX57: 1.0509539e+13 | DY57: =(DX57/DX53-1)*100 -> 6.8072163 | DZ57: 86.95 | EA57: =DY57/DZ57 -> 0.078288859 | EB57: 40179 | EC57: 6.6017709e+12 | ED57: =(EC57/EC53-1)*100 -> 24.274361 | EE57: =ED57/DZ57 -> 0.27917609 | EF57: 40179 | EG57: 2.3526773e+12 | EH57: =(EG57/EG53-1)*100 -> 12.823339 | EI57: =EH57/DZ57 -> 0.14747946 | EJ57: 22190 | EK57: 5.88 | EL57: =(EK57/EK53-1)*100 -> 837.79904
A58: 30682 | B58: 9.431691 | C58: =(B58/B54-1)*100 -> 12.349967 | G58: 40269 | H58: 45.567464 | I58: 40269 | J58: 1.0960151e+13 | K58: =J58/H58 -> 2.405258e+11 | L58: =(K58/K54-1)*100 -> 15.925709 | O58: 40269 | P58: 6.685079e+12 | Q58: =P58/H58 -> 1.4670729e+11 | R58: =(Q58/Q54-1)*100 -> 19.90903 | S58: 40269 | T58: 1.9511367e+12 | U58: =T58/H58 -> 4.2818638e+10 | V58: =(U58/U54-1)*100 -> 16.420502 | X58: 22282 | DW58: 40269 | DX58: 1.0960151e+13 | DY58: =(DX58/DX54-1)*100 -> 8.4988234 | DZ58: 86.95 | EA58: =DY58/DZ58 -> 0.0977438 | EB58: 40269 | EC58: 6.685079e+12 | ED58: =(EC58/EC54-1)*100 -> 12.226949 | EE58: =ED58/DZ58 -> 0.14062046 | EF58: 40269 | EG58: 1.9511367e+12 | EH58: =(EG58/EG54-1)*100 -> 8.9619173 | EI58: =EH58/DZ58 -> 0.10306978 | EJ58: 22282 | EK58: 5.902 | EL58: =(EK58/EK54-1)*100 -> 106.50805
A59: 30773 | B59: 9.504532 | C59: =(B59/B55-1)*100 -> 8.4950004 | G59: 40360 | H59: 46.382773 | I59: 40360 | J59: 1.1286216e+13 | K59: =J59/H59 -> 2.4332775e+11 | L59: =(K59/K55-1)*100 -> 13.306795 | O59: 40360 | P59: 6.8987679e+12 | Q59: =P59/H59 -> 1.4873557e+11 | R59: =(Q59/Q55-1)*100 -> 15.467658 | S59: 40360 | T59: 1.8889914e+12 | U59: =T59/H59 -> 4.0726142e+10 | V59: =(U59/U55-1)*100 -> 12.832837 | X59: 22372 | DW59: 40360 | DX59: 1.1286216e+13 | DY59: =(DX59/DX55-1)*100 -> 8.8032378 | DZ59: 86.95 | EA59: =DY59/DZ59 -> 0.10124483 | EB59: 40360 | EC59: 6.8987679e+12 | ED59: =(EC59/EC55-1)*100 -> 10.878214 | EE59: =ED59/DZ59 -> 0.12510885 | EF59: 40360 | EG59: 1.8889914e+12 | EH59: =(EG59/EG55-1)*100 -> 8.3481188 | EI59: =EH59/DZ59 -> 0.096010566 | EJ59: 22372 | EK59: 4.727 | EL59: =(EK59/EK55-1)*100 -> 39.234168
A60: 30864 | B60: 9.869951 | C60: =(B60/B56-1)*100 -> 7.0582081 | G60: 40452 | H60: 44.792815 | I60: 40452 | J60: 1.1296946e+13 | K60: =J60/H60 -> 2.5220443e+11 | L60: =(K60/K56-1)*100 -> 11.725523 | O60: 40452 | P60: 7.1810578e+12 | Q60: =P60/H60 -> 1.6031718e+11 | R60: =(Q60/Q56-1)*100 -> 18.595399 | S60: 40452 | T60: 2.4782328e+12 | U60: =T60/H60 -> 5.532657e+10 | V60: =(U60/U56-1)*100 -> 6.7433259 | X60: 22463 | DW60: 40452 | DX60: 1.1296946e+13 | DY60: =(DX60/DX56-1)*100 -> 7.4824166 | DZ60: 86.95 | EA60: =DY60/DZ60 -> 0.086054245 | EB60: 40452 | EC60: 7.1810578e+12 | ED60: =(EC60/EC56-1)*100 -> 14.091388 | EE60: =ED60/DZ60 -> 0.16206312 | EF60: 40452 | EG60: 2.4782328e+12 | EH60: =(EG60/EG56-1)*100 -> 2.6894327 | EI60: =EH60/DZ60 -> 0.030930796 | EJ60: 22463 | EK60: 4.453 | EL60: =(EK60/EK56-1)*100 -> -4.8910722
A61: 30956 | B61: 9.953718 | C61: =(B61/B57-1)*100 -> 5.7935458 | G61: 40544 | H61: 45.215796 | I61: 40544 | J61: 1.1554586e+13 | K61: =J61/H61 -> 2.5554312e+11 | L61: =(K61/K57-1)*100 -> 11.559675 | O61: 40544 | P61: 7.0667005e+12 | Q61: =P61/H61 -> 1.5628831e+11 | R61: =(Q61/Q57-1)*100 -> 8.6157409 | S61: 40544 | T61: 2.4608138e+12 | U61: =T61/H61 -> 5.4423765e+10 | V61: =(U61/U57-1)*100 -> 6.1336086 | X61: 22555 | DW61: 40544 | DX61: 1.1554586e+13 | DY61: =(DX61/DX57-1)*100 -> 9.9437916 | DZ61: 86.95 | EA61: =DY61/DZ61 -> 0.11436218 | EB61: 40544 | EC61: 7.0667005e+12 | ED61: =(EC61/EC57-1)*100 -> 7.0424985 | EE61: =ED61/DZ61 -> 0.080994807 | EF61: 40544 | EG61: 2.4608138e+12 | EH61: =(EG61/EG57-1)*100 -> 4.5963186 | EI61: =EH61/DZ61 -> 0.052861628 | EJ61: 22555 | EK61: 4.572 | EL61: =(EK61/EK57-1)*100 -> -22.244898
A62: 31048 | B62: 9.863881 | C62: =(B62/B58-1)*100 -> 4.5823172 | G62: 40634 | H62: 44.667697 | I62: 40634 | J62: 1.263598e+13 | K62: =J62/H62 -> 2.8288855e+11 | L62: =(K62/K58-1)*100 -> 17.612559 | O62: 40634 | P62: 7.2605459e+12 | Q62: =P62/H62 -> 1.6254579e+11 | R62: =(Q62/Q58-1)*100 -> 10.795987 | S62: 40634 | T62: 2041651459000 | U62: =T62/H62 -> 4.5707561e+10 | V62: =(U62/U58-1)*100 -> 6.7468813 | X62: 22647 | DW62: 40634 | DX62: 1.263598e+13 | DY62: =(DX62/DX58-1)*100 -> 15.290202 | DZ62: 86.95 | EA62: =DY62/DZ62 -> 0.17585051 | EB62: 40634 | EC62: 7.2605459e+12 | ED62: =(EC62/EC58-1)*100 -> 8.6082286 | EE62: =ED62/DZ62 -> 0.099002054 | EF62: 40634 | EG62: 2041651459000 | EH62: =(EG62/EG58-1)*100 -> 4.6390758 | EI62: =EH62/DZ62 -> 0.053353374 | EJ62: 22647 | EK62: 4.01 | EL62: =(EK62/EK58-1)*100 -> -32.05693
A63: 31138 | B63: 10.09333 | C63: =(B63/B59-1)*100 -> 6.1949184 | G63: 40725 | H63: 45.77267 | I63: 40725 | J63: 1.1784083e+13 | K63: =J63/H63 -> 2.57448e+11 | L63: =(K63/K59-1)*100 -> 5.8029783 | O63: 40725 | P63: 7.4022916e+12 | Q63: =P63/H63 -> 1.6171859e+11 | R63: =(Q63/Q59-1)*100 -> 8.7289287 | S63: 40725 | T63: 2571467026000 | U63: =T63/H63 -> 5.6179091e+10 | V63: =(U63/U59-1)*100 -> 37.943563 | X63: 22737 | DW63: 40725 | DX63: 1.1784083e+13 | DY63: =(DX63/DX59-1)*100 -> 4.4112842 | DZ63: 86.95 | EA63: =DY63/DZ63 -> 0.050733573 | EB63: 40725 | EC63: 7.4022916e+12 | ED63: =(EC63/EC59-1)*100 -> 7.2987477 | EE63: =ED63/DZ63 -> 0.083941894 | EF63: 40725 | EG63: 2571467026000 | EH63: =(EG63/EG59-1)*100 -> 36.129103 | EI63: =EH63/DZ63 -> 0.41551585 | EJ63: 22737 | EK63: 4.777 | EL63: =(EK63/EK59-1)*100 -> 1.0577533
A64: 31229 | B64: 10.38591 | C64: =(B64/B60-1)*100 -> 5.2275741 | G64: 40817 | H64: 50.759376 | I64: 40817 | J64: 12095370912605 | K64: =J64/H64 -> 2.3828841e+11 | L64: =(K64/K60-1)*100 -> -5.5177535 | O64: 40817 | P64: 7.5687557e+12 | Q64: =P64/H64 -> 1.491105e+11 | R64: =(Q64/Q60-1)*100 -> -6.9903187 | S64: 40817 | T64: 2203750985000 | U64: =T64/H64 -> 4.3415644e+10 | V64: =(U64/U60-1)*100 -> -21.528401 | X64: 22828 | DW64: 40817 | DX64: 12095370912605 | DY64: =(DX64/DX60-1)*100 -> 7.0676137 | DZ64: 86.95 | EA64: =DY64/DZ64 -> 0.081283653 | EB64: 40817 | EC64: 7.5687557e+12 | ED64: =(EC64/EC60-1)*100 -> 5.3988976 | EE64: =ED64/DZ64 -> 0.062091979 | EF64: 40817 | EG64: 2203750985000 | EH64: =(EG64/EG60-1)*100 -> -11.075709 | EI64: =EH64/DZ64 -> -0.12738021 | EJ64: 22828 | EK64: 4.482 | EL64: =(EK64/EK60-1)*100 -> 0.65124635
A65: 31321 | B65: 10.57044 | C65: =(B65/B61-1)*100 -> 6.1958958 | G65: 40909 | H65: 50.209145 | I65: 40909 | J65: 1.2589039e+13 | K65: =J65/H65 -> 2.50732e+11 | L65: =(K65/K61-1)*100 -> -1.8827039 | O65: 40909 | P65: 7.7457336e+12 | Q65: =P65/H65 -> 1.5426938e+11 | R65: =(Q65/Q61-1)*100 -> -1.291802 | S65: 40909 | T65: 2866880531000 | U65: =T65/H65 -> 5.7098772e+10 | V65: =(U65/U61-1)*100 -> 4.9151467 | X65: 22920 | DW65: 40909 | DX65: 1.2589039e+13 | DY65: =(DX65/DX61-1)*100 -> 8.9527555 | DZ65: 86.95 | EA65: =DY65/DZ65 -> 0.10296441 | EB65: 40909 | EC65: 7.7457336e+12 | ED65: =(EC65/EC61-1)*100 -> 9.608913 | EE65: =ED65/DZ65 -> 0.11051079 | EF65: 40909 | EG65: 2866880531000 | EH65: =(EG65/EG61-1)*100 -> 16.501318 | EI65: =EH65/DZ65 -> 0.18977939 | EJ65: 22920 | EK65: 3.133 | EL65: =(EK65/EK61-1)*100 -> -31.474191
... A111: 35521 | B111: 29.32483 | C111: =(B111/B107-1)*100 -> 7.7157229 | G111: 45108 | H111: 82.671175 | I111: 45108 | J111: 2.4226269e+13 | K111: =J111/H111 -> 2.9304372e+11 | L111: =(K111/K107-1)*100 -> -0.36308824 | O111: 45108 | P111: 1.4916401e+13 | Q111: =P111/H111 -> 1.8043049e+11 | R111: =(Q111/Q107-1)*100 -> 6.3946629 | S111: 45108 | T111: 3735131772000 | U111: =T111/H111 -> 4.5180582e+10 | V111: =(U111/U107-1)*100 -> 8.4613833 | X111: 27120 | DW111: 45108 | DX111: 2.4226269e+13 | DY111: =(DX111/DX107-1)*100 -> 3.2107009 | DZ111: 86.95 | EA111: =DY111/DZ111 -> 0.03692583 | EB111: 45108 | EC111: 1.4916401e+13 | ED111: =(EC111/EC107-1)*100 -> 10.21084 | EE111: =ED111/DZ111 -> 0.11743347 | EF111: 45108 | EG111: 3735131772000 | EH111: =(EG111/EG107-1)*100 -> 12.35169 | EI111: =EH111/DZ111 -> 0.14205509 | EJ111: 27120 | EK111: -2.714 | EL111: =(EK111/EK107-1)*100 -> -210.59495
A112: 35612 | B112: 29.79469 | C112: =(B112/B108-1)*100 -> 5.0682236 | G112: 45200 | H112: 83.265786 | X112: 27211 | EJ112: 27211 | EK112: -6.972 | EL112: =(EK112/EK108-1)*100 -> -208.31133
A113: 35704 | B113: 30.48566 | C113: =(B113/B109-1)*100 -> 5.5502256 | G113: 45292 | H113: 83.043332 | X113: 27303 | EJ113: 27303 | EK113: 0.033 | EL113: =(EK113/EK109-1)*100 -> -99.631367
A114: 35796 | B114: 31.67413 | C114: =(B114/B110-1)*100 -> 9.0390052 | G114: 45383 | H114: 83.421531 | X114: 27395 | EJ114: 27395 | EK114: 16.481 | EL114: =(EK114/EK110-1)*100 -> 157.75727
A115: 35886 | B115: 32.3651 | C115: =(B115/B111-1)*100 -> 10.367562 | G115: 45474 | H115: 83.777365 | X115: 27485 | EJ115: 27485 | EK115: 21.582 | EL115: =(EK115/EK111-1)*100 -> -895.21002
A116: 35977 | B116: 34.38274 | C116: =(B116/B112-1)*100 -> 15.398885 | G116: 45566 | H116: 84.460133 | X116: 27576 | EJ116: 27576 | EK116: 12.043 | EL116: =(EK116/EK112-1)*100 -> -272.73379
A117: 36069 | B117: 35.93052 | C117: =(B117/B113-1)*100 -> 17.860397 | X117: 27668 | EJ117: 27668 | EK117: 13.801 | EL117: =(EK117/EK113-1)*100 -> 41721.212
A118: 36161 | B118: 34.52094 | C118: =(B118/B114-1)*100 -> 8.987808 | X118: 27760 | EJ118: 27760 | EK118: 4.65 | EL118: =(EK118/EK114-1)*100 -> -71.785693
A119: 36251 | B119: 34.65913 | C119: =(B119/B115-1)*100 -> 7.0879744 | X119: 27851 | EJ119: 27851 | EK119: -0.496 | EL119: =(EK119/EK115-1)*100 -> -102.29821
A120: 36342 | B120: 35.3501 | C120: =(B120/B116-1)*100 -> 2.8135047 | X120: 27942 | EJ120: 27942 | EK120: -4.073 | EL120: =(EK120/EK116-1)*100 -> -133.82048
...

Sheet india_clean
A1: Date | B1: headline_cpi_yy | C1: core_cpi_yy | D1: cons_yy | E1: gfcf_yy | F1: g_yy | G1: exports_yy
A2: 25934 | B2: =India!$C6 -> 3.5322639 | C2: #N/A | D2: #N/A | E2: #N/A | F2: #N/A | G2: #N/A
A3: 26024 | B3: =India!$C7 -> 1.1040862 | C3: #N/A | D3: #N/A | E3: #N/A | F3: #N/A | G3: #N/A
A4: 26115 | B4: =India!$C8 -> 3.3963585 | C4: #N/A | D4: #N/A | E4: #N/A | F4: #N/A | G4: #N/A
A5: 26207 | B5: =India!$C9 -> 4.2610431 | C5: #N/A | D5: #N/A | E5: #N/A | F5: #N/A | G5: #N/A
A6: 26299 | B6: =India!$C10 -> 5.2156818 | C6: #N/A | D6: #N/A | E6: #N/A | F6: #N/A | G6: #N/A
A7: 26390 | B7: =India!$C11 -> 6.6302743 | C7: #N/A | D7: #N/A | E7: #N/A | F7: #N/A | G7: #N/A
A8: 26481 | B8: =India!$C12 -> 6.9055627 | C8: #N/A | D8: #N/A | E8: #N/A | F8: #N/A | G8: #N/A
A9: 26573 | B9: =India!$C13 -> 6.958761 | C9: #N/A | D9: #N/A | E9: #N/A | F9: #N/A | G9: #N/A
A10: 26665 | B10: =India!$C14 -> 10.026111 | C10: #N/A | D10: #N/A | E10: #N/A | F10: #N/A | G10: #N/A
A11: 26755 | B11: =India!$C15 -> 15.21581 | C11: #N/A | D11: #N/A | E11: #N/A | F11: #N/A | G11: #N/A
A12: 26846 | B12: =India!$C16 -> 19.029337 | C12: #N/A | D12: #N/A | E12: #N/A | F12: #N/A | G12: #N/A
A13: 26938 | B13: =India!$C17 -> 22.891545 | C13: #N/A | D13: #N/A | E13: #N/A | F13: #N/A | G13: #N/A
... A106: 35431 | B106: =India!$C110 -> 10.631601 | C106: #N/A | D106: #N/A | E106: #N/A | F106: #N/A | G106: #N/A
A107: 35521 | B107: =India!$C111 -> 7.7157229 | C107: #N/A | D107: =India!$L6 -> -0.4734313 | E107: =India!$R6 -> 4.496281 | F107: =India!$V6 -> -2.733033 | G107: 745.06088
A108: 35612 | B108: =India!$C112 -> 5.0682236 | C108: #N/A | D108: =India!$L7 -> 2.7986978 | E108: =India!$R7 -> 4.7695214 | F108: =India!$V7 -> 9.3981372 | G108: -132.52648
A109: 35704 | B109: =India!$C113 -> 5.5502256 | C109: #N/A | D109: =India!$L8 -> -2.0697181 | E109: =India!$R8 -> 1.6297029 | F109: =India!$V8 -> 7.5465838 | G109: 68.211094
A110: 35796 | B110: =India!$C114 -> 9.0390052 | C110: #N/A | D110: =India!$L9 -> -5.7419306 | E110: =India!$R9 -> -4.637577 | F110: =India!$V9 -> 10.464426 | G110: 89.629431
A111: 35886 | B111: =India!$C115 -> 10.367562 | C111: #N/A | D111: =India!$L10 -> -3.127683 | E111: =India!$R10 -> -6.2061236 | F111: =India!$V10 -> 20.250606 | G111: 308.76622
A112: 35977 | B112: =India!$C116 -> 15.398885 | C112: #N/A | D112: =India!$L11 -> -7.3186563 | E112: =India!$R11 -> -8.8493356 | F112: =India!$V11 -> 2.1916218 | G112: 199.07727
A113: 36069 | B113: =India!$C117 -> 17.860397 | C113: #N/A | D113: =India!$L12 -> -13.867119 | E113: =India!$R12 -> -5.0143417 | F113: =India!$V12 -> -7.8776837 | G113: -4.5405374
A114: 36161 | B114: =India!$C118 -> 8.987808 | C114: #N/A | D114: =India!$L13 -> 1.1294285 | E114: =India!$R13 -> 0.084311647 | F114: =India!$V13 -> -13.134584 | G114: -76.035089
A115: 36251 | B115: =India!$C119 -> 7.0879744 | C115: #N/A | D115: =India!$L14 -> -2.4878099 | E115: =India!$R14 -> 6.2712103 | F115: =India!$V14 -> -2.6734824 | G115: -88.796897
A116: 36342 | B116: =India!$C120 -> 2.8135047 | C116: #N/A | D116: =India!$L15 -> 0.15340732 | E116: =India!$R15 -> 9.7568473 | F116: =India!$V15 -> 11.843824 | G116: -14.862084
A117: 36434 | B117: =India!$C121 -> 0.46152964 | C117: #N/A | D117: =India!$L16 -> 14.670864 | E117: =India!$R16 -> 7.1185991 | F117: =India!$V16 -> 23.16873 | G117: 10.492537
A118: 36526 | B118: =India!$C122 -> 3.682924 | C118: #N/A | D118: =India!$L17 -> 0.70296101 | E118: =India!$R17 -> 8.479938 | F118: =India!$V17 -> 9.2578645 | G118: 183.59883
... A165: 40817 | B165: =India!$C169 -> 8.3941652 | C165: #N/A | D165: =India!$L64 -> -5.5177535 | E165: =India!$R64 -> -6.9903187 | F165: =India!$V64 -> -21.528401 | G165: 129.49232
A166: 40909 | B166: =India!$C170 -> 7.1684667 | C166: =India!$F6 -> 10.163064 | D166: =India!$L65 -> -1.8827039 | E166: =India!$R65 -> -1.291802 | F166: =India!$V65 -> 4.9151467 | G166: 165.63688
A167: 41000 | B167: =India!$C171 -> 10.142348 | C167: =India!$F7 -> 9.5431098 | D167: =India!$L66 -> -17.79866 | E167: =India!$R66 -> -10.812546 | F167: =India!$V66 -> -7.2603686 | G167: -11.300632
A168: 41091 | B168: =India!$C172 -> 9.7602733 | C168: =India!$F8 -> 9.009009 | D168: =India!$L67 -> -9.4734709 | E168: =India!$R67 -> -12.198141 | F168: =India!$V67 -> -7.5774865 | G168: -42.893786
A169: 41183 | B169: =India!$C173 -> 10.101007 | C169: =India!$F9 -> 8.8927944 | D169: =India!$L68 -> 2.0277884 | E169: =India!$R68 -> -3.1751736 | F169: =India!$V68 -> -19.34958 | G169: 21.873552
A170: 41275 | B170: =India!$C174 -> 11.705678 | C170: =India!$F10 -> 8.5714286 | D170: =India!$L69 -> -2.600112 | E170: =India!$R69 -> -4.4020032 | F170: =India!$V69 -> -12.803896 | G170: -6.7995338
A171: 41365 | B171: =India!$C175 -> 10.662367 | C171: =India!$F11 -> 7.2990246 | D171: =India!$L70 -> 4.004798 | E171: =India!$R70 -> -1.9045325 | F171: =India!$V70 -> 14.817981 | G171: -32.442397
A172: 41456 | B172: =India!$C176 -> 10.764437 | C172: =India!$F12 -> 7.7024793 | D172: =India!$L71 -> -5.8245335 | E172: =India!$R71 -> -10.168446 | F172: =India!$V71 -> -13.377367 | G172: -65.411691
A173: 41548 | B173: =India!$C177 -> 10.550452 | C173: =India!$F13 -> 6.9722402 | D173: =India!$L72 -> -5.9786193 | E173: =India!$R72 -> -10.138465 | F173: =India!$V72 -> -9.9843113 | G173: -94.155757
A174: 41640 | B174: =India!$C178 -> 6.8862316 | C174: =India!$F14 -> 6.7850349 | D174: =India!$L73 -> -5.5957641 | E174: =India!$R73 -> -11.868391 | F174: =India!$V73 -> -24.30202 | G174: -80.170616
A175: 41730 | B175: =India!$C179 -> 6.8613171 | C175: =India!$F15 -> 6.8025078 | D175: =India!$L74 -> 0.077740567 | E175: =India!$R74 -> -4.5292328 | F175: =India!$V74 -> -4.3226937 | G175: -76.090507
A176: 41821 | B176: =India!$C180 -> 6.760555 | C176: =India!$F16 -> 5.801105 | D176: =India!$L75 -> 10.794151 | E176: =India!$R75 -> 6.9029977 | F176: =India!$V75 -> 12.850394 | G176: 57.217846
A177: 41913 | B177: =India!$C181 -> 4.9792499 | C177: =India!$F17 -> 4.6771273 | D177: =India!$L76 -> 3.4605898 | E177: =India!$R76 -> 0.90327857 | F177: =India!$V76 -> 29.024792 | G177: 201.22395
... A212: 45108 | B212: =India!$C216 -> 6.3873023 | C212: =India!$F52 -> 4.7239502 | D212: =India!$L111 -> -0.36308824 | E212: =India!$R111 -> 6.3946629 | F212: =India!$V111 -> 8.4613833 | G212: 87.153367
...

Sheet Brazil
A1: Year | B1: headline_cpi_quarterly | C1: headline_cpi_yy | D1: Year | E1: core_cpi_quarterly | F1: core_cpi_yy | H1: observation_date | I1: ex_rate_quarterly_avg | J1: Year | K1: cons_quarterly(current prices) | L1: gdp deflator | M1: cons_quarterly(constant prices) | N1: cons_quarterly($) | O1: cons_yy | Q1: Year | R1: GFCF_quarterly(constant prices) | S1: gfcf_quarterly($) | T1: gfcf_yy | U1: Year | V1: g_quarterly (constant prices) | W1: g_quarterly($) | X1: g_yy | Z1: Year | AA1: imports_quarterly | AB1: exports_quarterly | AC1: netx_quarterly | AD1: netx_quarterly ($) | AE1: netx_yy
A2: 33695 | B2: 0.07353174 | C2: N/A | D2: 34700 | E2: 1885260.9 | F2: N/A | H2: 35065 | I2: 0.98009176 | J2: 35065 | K2: 1.2994117e+11 | L2: 22.618803 | M2: =(K2/L2)*100 -> 5.7448299e+11 | N2: =M2/I2 -> 5.8615225e+11 | O2: N/A | Q2: 35065 | R2: 34673475900 | S2: =R2/I2 -> 3.5377785e+10 | T2: N/A | U2: 35065 | V2: 36624150540 | W2: =V2/I2 -> 3.7368083e+10 | X2: N/A | Z2: 17168
A3: 33786 | B3: 0.1502193 | C3: N/A | D3: 34790 | E3: 2031193.9 | F3: N/A | H3: 35156 | I3: 0.99517552 | J3: 35156 | K3: 1.3417246e+11 | L3: 23.268626 | M3: =(K3/L3)*100 -> 5.7662391e+11 | N3: =M3/I3 -> 5.794193e+11 | O3: N/A | Q3: 35156 | R3: 35344872620 | S3: =R3/I3 -> 3.551622e+10 | T3: N/A | U3: 35156 | V3: 37213622140 | W3: =V3/I3 -> 3.7394029e+10 | X3: N/A | Z3: 17258
A4: 33878 | B4: 0.312971 | C4: N/A | D4: 34881 | E4: 2176146.2 | F4: N/A | H4: 35247 | I4: 1.012564 | J4: 35247 | K4: 1.4078778e+11 | L4: 23.597846 | M4: =(K4/L4)*100 -> 5.9661285e+11 | N4: =M4/I4 -> 5.8921002e+11 | O4: N/A | Q4: 35247 | R4: 36668150530 | S4: =R4/I4 -> 3.6213169e+10 | T4: N/A | U4: 35247 | V4: 38505969840 | W4: =V4/I4 -> 3.8028184e+10 | X4: N/A | Z4: 17349
A5: 33970 | B5: 0.7133014 | C5: N/A | D5: 34973 | E5: 2287866.6 | F5: N/A | H5: 35339 | I5: 1.0303305 | J5: 35339 | K5: 1.5203958e+11 | L5: 25.029142 | M5: =(K5/L5)*100 -> 6.0745024e+11 | N5: =M5/I5 -> 5.8956832e+11 | O5: N/A | Q5: 35339 | R5: 38230652190 | S5: =R5/I5 -> 3.710523e+10 | T5: N/A | U5: 35339 | V5: 32711751630 | W5: =V5/I5 -> 3.1748793e+10 | X5: N/A | Z5: 17441
A6: 34060 | B6: 1.755453 | C6: =(B6/B2-1)*100 -> 2287.3405 | D6: 35065 | E6: 2380679.4 | F6: N/A | H6: 35431 | I6: 1.0491958 | J6: 35431 | K6: 1.5225163e+11 | L6: 24.944879 | M6: =(K6/L6)*100 -> 6.1035226e+11 | N6: =M6/I6 -> 5.817334e+11 | O6: =(N6/N2-1)*100 -> -0.75387332 | Q6: 35431 | R6: 38556303460 | S6: =R6/I6 -> 3.6748434e+10 | T6: =(S6/S2-1)*100 -> 3.8743189 | U6: 35431 | V6: 37055431590 | W6: =V6/I6 -> 3.5317936e+10 | X6: =(W6/W2-1)*100 -> -5.4863587 | Z6: 17533
A7: 34151 | B7: 4.814175 | C7: =(B7/B3-1)*100 -> 3104.7646 | D7: 35156 | E7: 2442714.2 | F7: =(E7/E2-1)*100 -> 29.569031 | H7: 35521 | I7: 1.0675217 | J7: 35521 | K7: 1.5607186e+11 | L7: 25.214656 | M7: =(K7/L7)*100 -> 6.1897279e+11 | N7: =M7/I7 -> 5.7982218e+11 | O7: =(N7/N3-1)*100 -> 0.069531951 | Q7: 35521 | R7: 39099687570 | S7: =R7/I7 -> 3.6626596e+10 | T7: =(S7/S3-1)*100 -> 3.1263915 | U7: 35521 | V7: 36906115790 | W7: =V7/I7 -> 3.457177e+10 | X7: =(W7/W3-1)*100 -> -7.5473526 | Z7: 17624
A8: 34243 | B8: 14.24949 | C8: =(B8/B4-1)*100 -> 4452.9746 | D8: 35247 | E8: 2512318.1 | F8: =(E8/E3-1)*100 -> 23.68677 | H8: 35612 | I8: 1.0869699 | J8: 35612 | K8: 1.558749e+11 | L8: 25.742644 | M8: =(K8/L8)*100 -> 6.055124e+11 | N8: =M8/I8 -> 5.5706454e+11 | O8: =(N8/N4-1)*100 -> -5.4556909 | Q8: 35612 | R8: 39864202740 | S8: =R8/I8 -> 3.6674615e+10 | T8: =(S8/S4-1)*100 -> 1.2742495 | U8: 35612 | V8: 36327022610 | W8: =V8/I8 -> 3.3420449e+10 | X8: =(W8/W4-1)*100 -> -12.116632 | Z8: 17715
A9: 34335 | B9: 21.62461 | C9: =(B9/B5-1)*100 -> 2931.6231 | D9: 35339 | E9: 2556628.4 | F9: =(E9/E4-1)*100 -> 17.48422 | H9: 35704 | I9: 1.1065829 | J9: 35704 | K9: 1.5760861e+11 | L9: 25.629991 | M9: =(K9/L9)*100 -> 6.1493821e+11 | N9: =M9/I9 -> 5.557091e+11 | O9: =(N9/N5-1)*100 -> -5.7430514 | Q9: 35704 | R9: 39603386290 | S9: =R9/I9 -> 3.57889e+10 | T9: =(S9/S5-1)*100 -> -3.5475589 | U9: 35704 | V9: 36587191240 | W9: =V9/I9 -> 3.3063217e+10 | X9: =(W9/W5-1)*100 -> 4.1400732 | Z9: 17807
A10: 34425 | B10: 23.10756 | C10: =(B10/B6-1)*100 -> 1216.3303 | D10: 35431 | E10: 2595399.9 | F10: =(E10/E5-1)*100 -> 13.441928 | H10: 35796 | I10: 1.1258539 | J10: 35796 | K10: 1.6110327e+11 | L10: 26.481394 | M10: =(K10/L10)*100 -> 6.08364e+11 | N10: =M10/I10 -> 5.4035786e+11 | O10: =(N10/N6-1)*100 -> -7.1124573 | Q10: 35796 | R10: 39818689110 | S10: =R10/I10 -> 3.5367546e+10 | T10: =(S10/S6-1)*100 -> -3.7576785 | U10: 35796 | V10: 37462419580 | W10: =V10/I10 -> 3.3274672e+10 | X10: =(W10/W6-1)*100 -> -5.7853434 | Z10: 17899
A11: 34516 | B11: 24.27226 | C11: =(B11/B7-1)*100 -> 404.18317 | D11: 35521 | E11: 2642805.4 | F11: =(E11/E6-1)*100 -> 11.010554 | H11: 35886 | I11: 1.1467777 | J11: 35886 | K11: 1.6087726e+11 | L11: 26.787543 | M11: =(K11/L11)*100 -> 6.0056744e+11 | N11: =M11/I11 -> 5.2369994e+11 | O11: =(N11/N7-1)*100 -> -9.6792159 | Q11: 35886 | R11: 39966912450 | S11: =R11/I11 -> 3.4851489e+10 | T11: =(S11/S7-1)*100 -> -4.8464962 | U11: 35886 | V11: 37712684930 | W11: =V11/I11 -> 3.2885784e+10 | X11: =(W11/W7-1)*100 -> -4.8767707 | Z11: 17989
A12: 34608 | B12: 25.84554 | C12: =(B12/B8-1)*100 -> 81.378702 | D12: 35612 | E12: 2673168.1 | F12: =(E12/E7-1)*100 -> 9.4343346 | H12: 35977 | I12: 1.169829 | J12: 35977 | K12: 1.6215663e+11 | L12: 26.892205 | M12: =(K12/L12)*100 -> 6.0298749e+11 | N12: =M12/I12 -> 5.1544925e+11 | O12: =(N12/N8-1)*100 -> -7.4704617 | Q12: 35977 | R12: 39449630480 | S12: =R12/I12 -> 3.3722561e+10 | T12: =(S12/S8-1)*100 -> -8.0493108 | U12: 35977 | V12: 38367487230 | W12: =V12/I12 -> 3.2797517e+10 | X12: =(W12/W8-1)*100 -> -1.8639248 | Z12: 18080
A13: 34700 | B13: 27.35299 | C13: =(B13/B9-1)*100 -> 26.490096 | D13: 35704 | E13: 2697230.9 | F13: =(E13/E8-1)*100 -> 7.3602435 | H13: 36069 | I13: 1.193967 | J13: 36069 | K13: 1.5879384e+11 | L13: 26.36305 | M13: =(K13/L13)*100 -> 6.0233485e+11 | N13: =M13/I13 -> 5.0448198e+11 | O13: =(N13/N9-1)*100 -> -9.2183351 | Q13: 36069 | R13: 37671459410 | S13: =R13/I13 -> 3.1551507e+10 | T13: =(S13/S9-1)*100 -> -11.839964 | U13: 36069 | V13: 38084500640 | W13: =V13/I13 -> 3.1897448e+10 | X13: =(W13/W9-1)*100 -> -3.5258793 | Z13: 18172
A14: 34790 | B14: 28.43479 | C14: =(B14/B10-1)*100 -> 23.054057 | D14: 35796 | E14: 2717759.4 | F14: =(E14/E9-1)*100 -> 6.3024803 | H14: 36161 | I14: 1.768694 | J14: 36161 | K14: 1.6889396e+11 | L14: 27.890225 | M14: =(K14/L14)*100 -> 6.0556685e+11 | N14: =M14/I14 -> 3.4238079e+11 | O14: =(N14/N10-1)*100 -> -36.638141 | Q14: 36161 | R14: 36330245470 | S14: =R14/I14 -> 2.0540718e+10 | T14: =(S14/S10-1)*100 -> -41.922127 | U14: 36161 | V14: 37651523140 | W14: =V14/I14 -> 2.1287754e+10 | X14: =(W14/W10-1)*100 -> -36.024152 | Z14: 18264
A15: 34881 | B15: 29.48983 | C15: =(B15/B11-1)*100 -> 21.496021 | D15: 35886 | E15: 2721504.5 | F15: =(E15/E10-1)*100 -> 4.8587721 | H15: 36251 | I15: 1.7129505 | J15: 36251 | K15: 1.7228025e+11 | L15: 28.678918 | M15: =(K15/L15)*100 -> 6.0072088e+11 | N15: =M15/I15 -> 3.5069365e+11 | O15: =(N15/N11-1)*100 -> -33.035384 | Q15: 36251 | R15: 35890347780 | S15: =R15/I15 -> 2.0952355e+10 | T15: =(S15/S11-1)*100 -> -39.881034 | U15: 36251 | V15: 38074008110 | W15: =V15/I15 -> 2.222715e+10 | X15: =(W15/W11-1)*100 -> -32.411069 | Z15: 18354
A16: 34973 | B16: 30.39784 | C16: =(B16/B12-1)*100 -> 17.613484 | D16: 35977 | E16: 2721990.5 | F16: =(E16/E11-1)*100 -> 2.9962491 | H16: 36342 | I16: 1.8586364 | J16: 36342 | K16: 1.7778311e+11 | L16: 28.781949 | M16: =(K16/L16)*100 -> 6.1768961e+11 | N16: =M16/I16 -> 3.3233484e+11 | O16: =(N16/N12-1)*100 -> -35.525207 | Q16: 36342 | R16: 35048662600 | S16: =R16/I16 -> 1.8857192e+10 | T16: =(S16/S12-1)*100 -> -44.081376 | U16: 36342 | V16: 38865646410 | W16: =V16/I16 -> 2.0910839e+10 | X16: =(W16/W12-1)*100 -> -36.242614 | Z16: 18445
A17: 35065 | B17: 31.2095 | C17: =(B17/B13-1)*100 -> 14.099044 | D17: 36069 | E17: 2733715 | F17: =(E17/E12-1)*100 -> 2.2649867 | H17: 36434 | I17: 1.9151825 | J17: 36434 | K17: 1.8457468e+11 | L17: 29.686241 | M17: =(K17/L17)*100 -> 6.2175161e+11 | N17: =M17/I17 -> 3.2464352e+11 | O17: =(N17/N13-1)*100 -> -35.648143 | Q17: 36434 | R17: 35756866810 | S17: =R17/I17 -> 1.8670213e+10 | T17: =(S17/S13-1)*100 -> -40.826239 | U17: 36434 | V17: 39591032100 | W17: =V17/I17 -> 2.0672198e+10 | X17: =(W17/W13-1)*100 -> -35.191687 | Z17: 18537
A18: 35156 | B18: 31.49665 | C18: =(B18/B14-1)*100 -> 10.768006 | D18: 36161 | E18: 2767225.6 | F18: =(E18/E13-1)*100 -> 2.5950578 | H18: 36526 | I18: 1.7760099 | J18: 36526 | K18: 1.800774e+11 | L18: 29.806481 | M18: =(K18/L18)*100 -> 6.0415521e+11 | N18: =M18/I18 -> 3.4017559e+11 | O18: =(N18/N14-1)*100 -> -0.64407725 | Q18: 36526 | R18: 36017686600 | S18: =R18/I18 -> 2.0280116e+10 | T18: =(S18/S14-1)*100 -> -1.2687087 | U18: 36526 | V18: 38899746130 | W18: =V18/I18 -> 2.1902889e+10 | X18: =(W18/W14-1)*100 -> 2.8896173 | Z18: 18629
... A112: 43739 | B112: 123.5002 | C112: =(B112/B108-1)*100 -> 2.1363415 | D112: 44743 | E112: 11031852 | F112: =(E112/E107-1)*100 -> 11.39654 | H112: 45108 | I112: 4.8807765 | J112: 45108 | K112: 1.7380218e+12 | L112: 166.24778 | M112: =(K112/L112)*100 -> 1.0454406e+12 | N112: =M112/I112 -> 2.1419556e+11 | O112: =(N112/N108-1)*100 -> 12.440297 | Q112: 45108 | R112: 57824853830 | S112: =R112/I112 -> 1.184747e+10 | T112: =(S112/S108-1)*100 -> 0.20017622 | U112: 45108 | V112: 57067240640 | W112: =V112/I112 -> 1.1692246e+10 | X112: =(W112/W108-1)*100 -> 8.2663791 | Z112: 27211
A113: 43831 | B113: 124.4655 | C113: =(B113/B109-1)*100 -> 2.626482 | D113: 44835 | E113: 11214158 | F113: =(E113/E108-1)*100 -> 10.744984 | H113: 45200 | I113: 4.95376 | Z113: 27303
A114: 43922 | B114: 127.4925 | C114: =(B114/B110-1)*100 -> 4.2506513 | D114: 44927 | E114: 11409231 | F114: =(E114/E109-1)*100 -> 9.9502595 | H114: 45292 | I114: 4.952101 | Z114: 27395
A115: 44013 | B115: 130.4809 | C115: =(B115/B111-1)*100 -> 5.2855431 | D115: 45017 | E115: 11594422 | F115: =(E115/E110-1)*100 -> 9.304558 | H115: 45383 | I115: 5.2182275 | Z115: 27485
A116: 44105 | B116: 133.0346 | C116: =(B116/B112-1)*100 -> 7.7201494 | D116: 45108 | E116: 11706125 | F116: =(E116/E111-1)*100 -> 8.0287099 | H116: 45474 | I116: 5.5451094 | Z116: 27576
A117: 44197 | B117: 136.4667 | C117: =(B117/B113-1)*100 -> 9.64219 | D117: 45200 | E117: 11838318 | F117: =(E117/E112-1)*100 -> 7.3103443 | H117: 45566 | I117: 5.8424698 | Z117: 27668
A118: 44287 | B118: 140.8642 | C118: =(B118/B114-1)*100 -> 10.488225 | D118: 45292 | Z118: 27760
A119: 44378 | B119: 144.4992 | C119: =(B119/B115-1)*100 -> 10.743565 | D119: 45383 | Z119: 27851
A120: 44470 | B120: 148.8869 | C120: =(B120/B116-1)*100 -> 11.915923 | D120: 45474 | Z120: 27942
A121: 44562 | B121: 148.2647 | C121: =(B121/B117-1)*100 -> 8.6453325 | D121: 45566 | Z121: 28034
A122: 44652 | B122: 149.3866 | C122: =(B122/B118-1)*100 -> 6.0500823 | Z122: 28126
A123: 44743 | B123: 152.2088 | C123: =(B123/B119-1)*100 -> 5.3353929 | Z123: 28216
A124: 44835 | B124: 154.4831 | C124: =(B124/B120-1)*100 -> 3.758692 | Z124: 28307
A125: 44927 | B125: 155.076 | C125: =(B125/B121-1)*100 -> 4.5940133 | Z125: 28399
A126: 45017 | B126: 156.4192 | C126: =(B126/B122-1)*100 -> 4.7076512 | Z126: 28491
Z127: 28581
Z128: 28672
Z129: 28764
Z130: 28856
Z131: 28946
Z132: 29037
Z133: 29129
...

Sheet brazil_clean
A1: Date | B1: headline_cpi_yy | C1: core_cpi_yy | D1: cons_yy | E1: g_yy | F1: gfcf_yy | G1: exports_yy
A2: 34060 | B2: =Brazil!C6 -> 2287.3405 | C2: #N/A | D2: #N/A | E2: #N/A | F2: #N/A | G2: #N/A
A3: 34151 | B3: =Brazil!C7 -> 3104.7646 | C3: #N/A | D3: #N/A | E3: #N/A | F3: #N/A | G3: #N/A
A4: 34243 | B4: =Brazil!C8 -> 4452.9746 | C4: #N/A | D4: #N/A | E4: #N/A | F4: #N/A | G4: #N/A
A5: 34335 | B5: =Brazil!C9 -> 2931.6231 | C5: #N/A | D5: #N/A | E5: #N/A | F5: #N/A | G5: #N/A
A6: 34425 | B6: =Brazil!C10 -> 1216.3303 | C6: #N/A | D6: #N/A | E6: #N/A | F6: #N/A | G6: #N/A
A7: 34516 | B7: =Brazil!C11 -> 404.18317 | C7: #N/A | D7: #N/A | E7: #N/A | F7: #N/A | G7: #N/A
A8: 34608 | B8: =Brazil!C12 -> 81.378702 | C8: #N/A | D8: #N/A | E8: #N/A | F8: #N/A | G8: #N/A
A9: 34700 | B9: =Brazil!C13 -> 26.490096 | C9: #N/A | D9: #N/A | E9: #N/A | F9: #N/A | G9: #N/A
A10: 34790 | B10: =Brazil!C14 -> 23.054057 | C10: #N/A | D10: #N/A | E10: #N/A | F10: #N/A | G10: #N/A
A11: 34881 | B11: =Brazil!C15 -> 21.496021 | C11: #N/A | D11: #N/A | E11: #N/A | F11: #N/A | G11: #N/A
A12: 34973 | B12: =Brazil!C16 -> 17.613484 | C12: #N/A | D12: #N/A | E12: #N/A | F12: #N/A | G12: #N/A
A13: 35065 | B13: =Brazil!C17 -> 14.099044 | C13: #N/A | D13: #N/A | E13: #N/A | F13: #N/A | G13: #N/A
A14: 35156 | B14: =Brazil!C18 -> 10.768006 | C14: =Brazil!$F7 -> 29.569031 | D14: #N/A | E14: #N/A | F14: #N/A | G14: #N/A
A15: 35247 | B15: =Brazil!C19 -> 9.0665494 | C15: =Brazil!$F8 -> 23.68677 | D15: #N/A | E15: #N/A | F15: #N/A | G15: #N/A
A16: 35339 | B16: =Brazil!C20 -> 7.7666045 | C16: =Brazil!$F9 -> 17.48422 | D16: #N/A | E16: #N/A | F16: #N/A | G16: #N/A
A17: 35431 | B17: =Brazil!C21 -> 5.7234496 | C17: =Brazil!$F10 -> 13.441928 | D17: =Brazil!$O6 -> -0.75387332 | E17: =Brazil!$X6 -> -5.4863587 | F17: =Brazil!$T6 -> 3.8743189 | G17: 135.59522
A18: 35521 | B18: =Brazil!C22 -> 5.3049451 | C18: =Brazil!$F11 -> 11.010554 | D18: =Brazil!$O7 -> 0.069531951 | E18: =Brazil!$X7 -> -7.5473526 | F18: =Brazil!$T7 -> 3.1263915 | G18: 38.344099
A19: 35612 | B19: =Brazil!C23 -> 4.6476538 | C19: =Brazil!$F12 -> 9.4343346 | D19: =Brazil!$O8 -> -5.4556909 | E19: =Brazil!$X8 -> -12.116632 | F19: =Brazil!$T8 -> 1.2742495 | G19: -0.19350163
A20: 35704 | B20: =Brazil!C24 -> 3.7348224 | C20: =Brazil!$F13 -> 7.3602435 | D20: =Brazil!$O9 -> -5.7430514 | E20: =Brazil!$X9 -> 4.1400732 | F20: =Brazil!$T9 -> -3.5475589 | G20: -29.335432
A21: 35796 | B21: =Brazil!C25 -> 2.6251252 | C21: =Brazil!$F14 -> 6.3024803 | D21: =Brazil!$O10 -> -7.1124573 | E21: =Brazil!$X10 -> -5.7853434 | F21: =Brazil!$T10 -> -3.7576785 | G21: -5.6815374
A22: 35886 | B22: =Brazil!C26 -> 1.8203647 | C22: =Brazil!$F15 -> 4.8587721 | D22: =Brazil!$O11 -> -9.6792159 | E22: =Brazil!$X11 -> -4.8767707 | F22: =Brazil!$T11 -> -4.8464962 | G22: -29.843053
A23: 35977 | B23: =Brazil!C27 -> 2.3032296 | C23: =Brazil!$F16 -> 2.9962491 | D23: =Brazil!$O12 -> -7.4704617 | E23: =Brazil!$X12 -> -1.8639248 | F23: =Brazil!$T12 -> -8.0493108 | G23: -12.33764
A24: 36069 | B24: =Brazil!C28 -> 3.2671811 | C24: =Brazil!$F17 -> 2.2649867 | D24: =Brazil!$O13 -> -9.2183351 | E24: =Brazil!$X13 -> -3.5258793 | F24: =Brazil!$T13 -> -11.839964 | G24: -23.769402
A25: 36161 | B25: =Brazil!C29 -> 5.5014568 | C25: =Brazil!$F18 -> 2.5950578 | D25: =Brazil!$O14 -> -36.638141 | E25: =Brazil!$X14 -> -36.024152 | F25: =Brazil!$T14 -> -41.922127 | G25: -81.163013
A26: 36251 | B26: =Brazil!C30 -> 8.361597 | C26: =Brazil!$F19 -> 3.5129833 | D26: =Brazil!$O15 -> -33.035384 | E26: =Brazil!$X15 -> -32.411069 | F26: =Brazil!$T15 -> -39.881034 | G26: -80.101149
A27: 36342 | B27: =Brazil!C31 -> 7.8726256 | C27: =Brazil!$F20 -> 4.8623093 | D27: =Brazil!$O16 -> -35.525207 | E27: =Brazil!$X16 -> -36.242614 | F27: =Brazil!$T16 -> -44.081376 | G27: -87.201086
A28: 36434 | B28: =Brazil!C32 -> 6.5827816 | C28: =Brazil!$F21 -> 6.9168942 | D28: =Brazil!$O17 -> -35.648143 | E28: =Brazil!$X17 -> -35.191687 | F28: =Brazil!$T17 -> -40.826239 | G28: -103.57672
... A122: 45017 | B122: =Brazil!C126 -> 4.7076512 | C122: =Brazil!$F115 -> 9.304558 | D122: =Brazil!$O111 -> 3.0603086 | E122: =Brazil!$X111 -> 1.5863548 | F122: =Brazil!$T111 -> -2.502224 | G122: -428.53397
A123: 45108 | B123: #N/A | C123: =Brazil!$F116 -> 8.0287099 | D123: =Brazil!$O112 -> 12.440297 | E123: =Brazil!$X112 -> 8.2663791 | F123: =Brazil!$T112 -> 0.20017622 | G123: -424.97004
A124: 45200 | B124: #N/A | C124: =Brazil!$F117 -> 7.3103443 | D124: #N/A | E124: #N/A | F124: #N/A | G124: #N/A
A125: 45292 | B125: #N/A | C125: #N/A | D125: #N/A | E125: #N/A | F125: #N/A | G125: #N/A
A126: 45383 | B126: #N/A | C126: #N/A | D126: #N/A | E126: #N/A | F126: #N/A | G126: #N/A
A127: 45474 | B127: #N/A | C127: #N/A | D127: #N/A | E127: #N/A | F127: #N/A | G127: #N/A
A128: 45566 | B128: #N/A | C128: #N/A | D128: #N/A | E128: #N/A | F128: #N/A | G128: #N/A

Sheet China
A1: Year | B1: headline_cpi_quarterly | C1: headline_yy | D1: Year | E1: core_cpi_quarterly | F1: core_yy | G1: Date | H1: cons_quarterly | I1: cons_yy | J1: Date | K1: Local government bond_quarterly | L1: g_yy | M1: Date | N1: I_quarterly | O1: I_yy | P1: Year | Q1: NetX_quarterly | R1: NetX_yy
A2: 31413 | B2: 26.055801 | C2: N/A | D2: 38353 | E2: 83.066667 | F2: N/A | G2: 42186 | H2: 253198.72 | I2: N/A | J2: 42736 | K2: 68.2 | L2: N/A | M2: 44197 | N2: 30.3 | O2: N/A | P2: 42644 | Q2: 53.851 | R2: N/A
A3: 31503 | B3: 25.914918 | C3: N/A | D3: 38443 | E3: 82.99 | F3: N/A | G3: 42278 | H3: 454381.61 | I3: N/A | J3: 42826 | K3: 72.58 | L3: N/A | M3: 44287 | N3: 15.966667 | O3: N/A | P3: 42736 | Q3: 14.989 | R3: N/A
A4: 31594 | B4: 25.537575 | C4: N/A | D4: 38534 | E4: 82.943333 | F4: N/A | G4: 42370 | H4: 356922.94 | I4: N/A | J4: 42917 | K4: 78.8 | L4: N/A | M4: 44378 | N4: 8.8333333 | O4: N/A | P4: 42826 | Q4: 30.207667 | R4: N/A
A5: 31686 | B5: 26.466671 | C5: N/A | D5: 38626 | E5: 83.08 | F5: N/A | G5: 42461 | H5: 375677.79 | I5: N/A | J5: 43009 | K5: 83.31 | L5: N/A | M5: 44470 | N5: 5.4 | O5: N/A | P5: 42917 | Q5: 28.042 | R5: N/A
A6: 31778 | B6: 27.471568 | C6: =(B6/B2-1)*100 -> 5.4335971 | D6: 38718 | E6: 83.266667 | F6: =(E6/E2-1)*100 -> 0.24077047 | G6: 42552 | H6: 289907.68 | I6: =(H6/H2-1)*100 -> 14.498083 | J6: 43101 | K6: 84.67 | L6: =(K6/K2-1)*100 -> 24.14956 | M6: 44562 | N6: 10.75 | O6: =(N6/N2-1)*100 -> -64.521452 | P6: 43009 | Q6: 44.015 | R6: =(Q6/Q2-1)*100 -> -18.265213
A7: 31868 | B7: 27.823909 | C7: =(B7/B3-1)*100 -> 7.3663783 | D7: 38808 | E7: 83.463333 | F7: =(E7/E3-1)*100 -> 0.57034984 | G7: 42644 | H7: 297695.36 | I7: =(H7/H3-1)*100 -> -34.483404 | J7: 43191 | K7: 87.85 | L7: =(K7/K3-1)*100 -> 21.038854 | M7: 44652 | N7: 6.3666667 | O7: =(N7/N3-1)*100 -> -60.125261 | P7: =P101/1/2018 -> 0 | Q7: 24.305 | R7: =(Q7/Q3-1)*100 -> 62.152245
A8: 31959 | B8: 27.554548 | C8: =(B8/B4-1)*100 -> 7.8980596 | D8: 38899 | E8: 83.61 | F8: =(E8/E4-1)*100 -> 0.8037616 | G8: 42736 | H8: 322554.14 | I8: =(H8/H4-1)*100 -> -9.6291945 | J8: 43282 | K8: 94.46 | L8: =(K8/K4-1)*100 -> 19.873096 | M8: 44743 | N8: 5.8 | O8: =(N8/N4-1)*100 -> -34.339623 | P8: 43191 | Q8: 34.644333 | R8: =(Q8/Q4-1)*100 -> 14.687221
A9: 32051 | B9: 28.646318 | C9: =(B9/B5-1)*100 -> 8.2354403 | D9: 38991 | E9: 83.773333 | F9: =(E9/E5-1)*100 -> 0.83453699 | G9: 42826 | H9: 325149.79 | I9: =(H9/H5-1)*100 -> -13.449822 | J9: 43374 | K9: 98.36 | L9: =(K9/K5-1)*100 -> 18.065058 | M9: 44835 | N9: 5.4 | O9: =(N9/N5-1)*100 -> 0 | P9: 43282 | Q9: 39.236667 | R9: =(Q9/Q5-1)*100 -> 39.921071
A10: 32143 | B10: 30.310997 | C10: =(B10/B6-1)*100 -> 10.335884 | D10: 39083 | E10: 83.996667 | F10: =(E10/E6-1)*100 -> 0.87670136 | G10: 42917 | H10: 315440.81 | I10: =(H10/H6-1)*100 -> 8.8073307 | J10: 43466 | K10: 100.74 | L10: =(K10/K6-1)*100 -> 18.979568 | M10: 44927 | N10: 5.3 | O10: =(N10/N6-1)*100 -> -50.697674 | P10: 43374 | Q10: 42.458667 | R10: =(Q10/Q6-1)*100 -> -3.5359158
A11: 32234 | B11: 31.786155 | C11: =(B11/B7-1)*100 -> 14.240437 | D11: 39173 | E11: 84.16 | F11: =(E11/E7-1)*100 -> 0.83469787 | G11: 43009 | H11: 294972.72 | I11: =(H11/H7-1)*100 -> -0.91457534 | J11: 43556 | K11: 104.65 | L11: =(K11/K7-1)*100 -> 19.123506 | M11: 45017 | N11: 4.1666667 | O11: =(N11/N7-1)*100 -> -34.554974 | P11: 43466 | Q11: 4.1246667 | R11: =(Q11/Q7-1)*100 -> -83.029555
A12: 32325 | B12: 33.915702 | C12: =(B12/B8-1)*100 -> 23.085678 | D12: 39264 | E12: 84.266667 | F12: =(E12/E8-1)*100 -> 0.7853925 | G12: 43101 | H12: 322974.68 | I12: =(H12/H8-1)*100 -> 0.13037817 | J12: 43647 | K12: 109.72 | L12: =(K12/K8-1)*100 -> 16.154986 | M12: 45108 | N12: 3.2333333 | O12: =(N12/N8-1)*100 -> -44.252874 | P12: 43556 | Q12: 51.268 | R12: =(Q12/Q8-1)*100 -> 47.983797
A13: 32417 | B13: 36.457977 | C13: =(B13/B9-1)*100 -> 27.269331 | D13: 39356 | E13: 84.606667 | F13: =(E13/E9-1)*100 -> 0.99474773 | G13: 43191 | H13: 294477.22 | I13: =(H13/H9-1)*100 -> -9.4333681 | J13: 43739 | K13: 112.26 | L13: =(K13/K9-1)*100 -> 14.131761 | M13: 45200 | N13: 2.9333333 | O13: =(N13/N9-1)*100 -> -45.679012 | P13: 43647 | Q13: 52.371333 | R13: =(Q13/Q9-1)*100 -> 33.475491
A14: 32509 | B14: 38.685977 | C14: =(B14/B10-1)*100 -> 27.630169 | D14: 39448 | E14: 84.94 | F14: =(E14/E10-1)*100 -> 1.1230604 | G14: 43282 | H14: 271202.23 | I14: =(H14/H10-1)*100 -> -14.02437 | J14: 43831 | K14: 116.47 | L14: =(K14/K10-1)*100 -> 15.614453 | M14: 45292 | N14: 4.35 | O14: =(N14/N10-1)*100 -> -17.924528 | P14: 43739 | Q14: 70.580667 | R14: =(Q14/Q10-1)*100 -> 66.233827
A15: 32599 | B15: 39.649191 | C15: =(B15/B11-1)*100 -> 24.737298 | D15: 39539 | E15: 85.143333 | F15: =(E15/E11-1)*100 -> 1.1684094 | G15: 43374 | H15: 273211.45 | I15: =(H15/H11-1)*100 -> -7.3773817 | J15: 43922 | K15: 121.94 | L15: =(K15/K11-1)*100 -> 16.521739 | M15: 45383 | N15: 4.0333333 | O15: =(N15/N11-1)*100 -> -3.2 | P15: 43831 | Q15: 35.988333 | R15: =(Q15/Q11-1)*100 -> 772.51495
A16: 32690 | B16: 39.1047 | C16: =(B16/B12-1)*100 -> 15.29969 | D16: 39630 | E16: 85.37 | F16: =(E16/E12-1)*100 -> 1.3093354 | G16: 43466 | H16: 248525.59 | I16: =(H16/H12-1)*100 -> -23.051061 | J16: 44013 | K16: 129.98 | L16: =(K16/K12-1)*100 -> 18.465184 | M16: 45474 | N16: 3.4666667 | O16: =(N16/N12-1)*100 -> 7.2164948 | P16: 43922 | Q16: 44.248667 | R16: =(Q16/Q12-1)*100 -> -13.691451
A17: 32782 | B17: 39.201113 | C17: =(B17/B13-1)*100 -> 7.5241034 | D17: 39722 | E17: 84.86 | F17: =(E17/E13-1)*100 -> 0.29942479 | G17: 43556 | H17: 200178.4 | I17: =(H17/H13-1)*100 -> -32.022448 | J17: 44105 | K17: 136.36 | L17: =(K17/K13-1)*100 -> 21.468021 | M17: 45566 | N17: 3.3 | O17: =(N17/N13-1)*100 -> 12.5 | P17: 44013 | Q17: 60.273667 | R17: =(Q17/Q13-1)*100 -> 15.089044
A18: 32874 | B18: 40.245007 | C18: =(B18/B14-1)*100 -> 4.0299612 | D18: 39814 | E18: 84.27 | F18: =(E18/E14-1)*100 -> -0.78879209 | G18: 43647 | H18: 208221.28 | I18: =(H18/H14-1)*100 -> -23.222871 | J18: 44197 | K18: 139.39 | L18: =(K18/K14-1)*100 -> 19.678887 | P18: 44105 | Q18: 82.959667 | R18: =(Q18/Q14-1)*100 -> 17.538797
A19: 32964 | B19: 40.57218 | C19: =(B19/B15-1)*100 -> 2.3278894 | D19: 39904 | E19: 84.033333 | F19: =(E19/E15-1)*100 -> -1.303684 | G19: 43739 | H19: 226390.47 | I19: =(H19/H15-1)*100 -> -17.137269 | J19: 44287 | K19: 143.33 | L19: =(K19/K15-1)*100 -> 17.541414 | P19: 44197 | Q19: 49.444333 | R19: =(Q19/Q15-1)*100 -> 37.389895
A20: 33055 | B20: 39.952624 | C20: =(B20/B16-1)*100 -> 2.1683422 | D20: 39995 | E20: 83.976667 | F20: =(E20/E16-1)*100 -> -1.6321112 | G20: 43831 | H20: 218387.29 | I20: =(H20/H16-1)*100 -> -12.12684 | J20: 44378 | K20: 148.8 | L20: =(K20/K16-1)*100 -> 14.479151 | P20: 44287 | Q20: 71.903333 | R20: =(Q20/Q16-1)*100 -> 62.498305
A21: 33147 | B21: 40.652307 | C21: =(B21/B17-1)*100 -> 3.7019211 | D21: 40087 | E21: 84.246667 | F21: =(E21/E17-1)*100 -> -0.72275905 | G21: 43922 | H21: 198860.59 | I21: =(H21/H17-1)*100 -> -0.65832037 | J21: 44470 | K21: 156.04 | L21: =(K21/K17-1)*100 -> 14.432385 | P21: 44378 | Q21: 85.795333 | R21: =(Q21/Q17-1)*100 -> 42.34298
A22: 33239 | B22: 40.99557 | C22: =(B22/B18-1)*100 -> 1.8649842 | D22: 40179 | E22: 84.476667 | F22: =(E22/E18-1)*100 -> 0.24524346 | G22: 44013 | H22: 190353.98 | I22: =(H22/H18-1)*100 -> -8.580923 | J22: 44562 | K22: 162.26 | L22: =(K22/K18-1)*100 -> 16.407203 | P22: 44470 | Q22: 72.166333 | R22: =(Q22/Q18-1)*100 -> -13.010338
A23: 33329 | B23: 41.829336 | C23: =(B23/B19-1)*100 -> 3.0985666 | D23: 40269 | E23: 84.753333 | F23: =(E23/E19-1)*100 -> 0.85680286 | G23: 44105 | H23: 199604.82 | I23: =(H23/H19-1)*100 -> -11.831617 | J23: 44652 | K23: 168.86 | L23: =(K23/K19-1)*100 -> 17.812042 | P23: 44562 | Q23: 60.318333 | R23: =(Q23/Q19-1)*100 -> 21.992409
A24: 33420 | B24: 41.830029 | C24: =(B24/B20-1)*100 -> 4.6990806 | D24: 40360 | E24: 84.993333 | F24: =(E24/E20-1)*100 -> 1.2106538 | G24: 44197 | H24: 274326.57 | I24: =(H24/H20-1)*100 -> 25.614715 | J24: 44743 | K24: 175.52 | L24: =(K24/K20-1)*100 -> 17.956989 | P24: 44652 | Q24: 73.252667 | R24: =(Q24/Q20-1)*100 -> 1.8765936
A25: 33512 | B25: 42.50846 | C25: =(B25/B21-1)*100 -> 4.5659211 | D25: 40452 | E25: 85.586667 | F25: =(E25/E21-1)*100 -> 1.5905674 | G25: 44287 | H25: 218804.73 | I25: =(H25/H21-1)*100 -> 10.029208 | J25: 44835 | K25: 179.35 | L25: =(K25/K21-1)*100 -> 14.938477 | P25: 44743 | Q25: 73.911667 | R25: =(Q25/Q21-1)*100 -> -13.851181
A26: 33604 | B26: 43.195481 | C26: =(B26/B22-1)*100 -> 5.3662174 | D26: 40544 | E26: 86.203333 | F26: =(E26/E22-1)*100 -> 2.0439569 | G26: 44378 | H26: 178269.36 | I26: =(H26/H22-1)*100 -> -6.3484954 | J26: 44927 | K26: 184.03 | L26: =(K26/K22-1)*100 -> 13.416739 | P26: 44835 | Q26: 66.551333 | R26: =(Q26/Q22-1)*100 -> -7.7806364
A27: 33695 | B27: 44.138278 | C27: =(B27/B23-1)*100 -> 5.5199092 | D27: 40634 | E27: 86.68 | F27: =(E27/E23-1)*100 -> 2.2732636 | G27: 44470 | H27: 191542.18 | I27: =(H27/H23-1)*100 -> -4.0393013 | J27: 45017 | K27: 189.07 | L27: =(K27/K23-1)*100 -> 11.968495 | P27: 44927 | Q27: 60.638 | R27: =(Q27/Q23-1)*100 -> 0.52996601
A28: 33786 | B28: 44.413222 | C28: =(B28/B24-1)*100 -> 6.1754503 | D28: 40725 | E28: 86.956667 | F28: =(E28/E24-1)*100 -> 2.3099851 | G28: 44562 | H28: 199713.53 | I28: =(H28/H24-1)*100 -> -27.19862 | J28: 45108 | K28: 195.27 | L28: =(K28/K24-1)*100 -> 11.252279 | P28: 45017 | Q28: 83.887667 | R28: =(Q28/Q24-1)*100 -> 14.518243
A29: 33878 | B29: 46.037945 | C29: =(B29/B25-1)*100 -> 8.3030189 | D29: 40817 | E29: 87.156667 | F29: =(E29/E25-1)*100 -> 1.8343979 | G29: 44652 | H29: 183237.77 | I29: =(H29/H25-1)*100 -> -16.255112 | J29: 45200 | K29: 206.36 | L29: =(K29/K25-1)*100 -> 15.059939 | P29: 45108 | Q29: 85.979333 | R29: =(Q29/Q25-1)*100 -> 16.327147
A30: 33970 | B30: 47.990978 | C30: =(B30/B26-1)*100 -> 11.101847 | D30: 40909 | E30: 87.383333 | F30: =(E30/E26-1)*100 -> 1.3688566 | G30: 44743 | H30: 166954.63 | I30: =(H30/H26-1)*100 -> -6.3469865 | J30: 45292 | K30: 211.93 | L30: =(K30/K26-1)*100 -> 15.160572 | P30: 45200 | Q30: 99.332 | R30: =(Q30/Q26-1)*100 -> 49.256213
A31: 34060 | B31: 50.552967 | C31: =(B31/B27-1)*100 -> 14.533167 | D31: 41000 | E31: 87.77 | F31: =(E31/E27-1)*100 -> 1.2574988 | G31: 44835 | H31: 156547.93 | I31: =(H31/H27-1)*100 -> -18.269733 | J31: 45383 | K31: 216.47 | L31: =(K31/K27-1)*100 -> 14.491987
A32: 34151 | B32: 51.574954 | C32: =(B32/B28-1)*100 -> 16.125225 | D32: 41091 | E32: 88.256667 | F32: =(E32/E28-1)*100 -> 1.4949975 | G32: 44927 | H32: 167004.94 | I32: =(H32/H28-1)*100 -> -16.377757 | J32: 45474 | K32: 226.23 | L32: =(K32/K28-1)*100 -> 15.85497
